<?xml version="1.0"?>
<robot xmlns:xacro="http://www.ros.org/wiki/xacro" name="ranger1s_sprayer">

  <xacro:property name="chassis_length" value="2.65"/>
  <xacro:property name="chassis_width" value="2.02"/>
  <xacro:property name="chassis_height" value="0.75"/>
  <xacro:property name="chassis_mass" value="600.0"/>
  
  <xacro:property name="wheel_radius" value="0.2"/>
  <xacro:property name="wheel_length" value="0.075"/>
  <xacro:property name="wheel_mass" value="5.0"/>
  
  <xacro:property name="wheel_offset_x" value="1.0"/> 
  <xacro:property name="wheel_offset_y" value="0.6375"/>
  <xacro:property name="wheel_offset_z" value="-0.925"/>

  <material name="grey"><color rgba="0.7 0.7 0.7 1"/></material>
  <material name="black"><color rgba="0.2 0.2 0.2 1"/></material>
  <material name="black_zed"><color rgba="0.1 0.1 0.1 1"/></material>

  <link name="base_footprint"/>

  <joint name="base_joint" type="fixed">
    <parent link="base_footprint"/>
    <child link="base_link"/>
    <origin xyz="0 0 1.125" rpy="0 0 0"/>
  </joint>

  <link name="base_link">
    <visual>
      <geometry>
        <box size="${chassis_length} ${chassis_width} ${chassis_height}"/>
      </geometry>
      <material name="grey"/>
    </visual>
    <collision>
      <geometry>
        <box size="${chassis_length} ${chassis_width} ${chassis_height}"/>
      </geometry>
    </collision>
    <inertial>
      <mass value="${chassis_mass}"/>
      <inertia ixx="232.0" ixy="0.0" ixz="0.0" iyy="379.0" iyz="0.0" izz="555.0"/>
    </inertial>
  </link>

  <xacro:macro name="wheel" params="prefix x_reflect y_reflect">
    <link name="${prefix}_wheel">
      <visual>
        <origin xyz="0 0 0" rpy="1.570796 0 0"/>
        <geometry>
          <cylinder radius="${wheel_radius}" length="${wheel_length}"/>
        </geometry>
        <material name="black"/>
      </visual>
      <collision>
        <origin xyz="0 0 0" rpy="1.570796 0 0"/>
        <geometry>
          <cylinder radius="${wheel_radius}" length="${wheel_length}"/>
        </geometry>
      </collision>
      <inertial>
        <mass value="${wheel_mass}"/>
        <inertia ixx="0.05" ixy="0" ixz="0" iyy="0.05" iyz="0" izz="0.1"/>
      </inertial>
    </link>

    <joint name="${prefix}_wheel_joint" type="continuous">
      <parent link="base_link"/>
      <child link="${prefix}_wheel"/>
      <origin xyz="${x_reflect * wheel_offset_x} ${y_reflect * wheel_offset_y} ${wheel_offset_z}" rpy="0 0 0"/>
      <axis xyz="0 1 0"/>
    </joint>
  </xacro:macro>

  <xacro:wheel prefix="front_left" x_reflect="1" y_reflect="1" />
  <xacro:wheel prefix="front_right" x_reflect="1" y_reflect="-1" />
  <xacro:wheel prefix="rear_left" x_reflect="-1" y_reflect="1" />
  <xacro:wheel prefix="rear_right" x_reflect="-1" y_reflect="-1" />

  <link name="zed_camera_link">
    <visual>
      <geometry>
        <box size="0.03 0.175 0.03"/>
      </geometry>
      <material name="black_zed"/>
    </visual>
    <collision>
      <geometry>
        <box size="0.03 0.175 0.03"/>
      </geometry>
    </collision>
    <inertial>
      <mass value="0.2"/>
      <inertia ixx="0.0001" ixy="0" ixz="0" iyy="0.0001" iyz="0" izz="0.0001"/>
    </inertial>
  </link>

  <joint name="zed_camera_joint" type="fixed">
    <parent link="base_link"/>
    <child link="zed_camera_link"/>
    <origin xyz="${chassis_length/2} 0 ${chassis_height/2 + 0.05}" rpy="0 0.7854 0"/>
  </joint>

  <gazebo reference="zed_camera_link">
    <sensor name="zed_camera" type="camera">
      <camera>
        <horizontal_fov>1.91986</horizontal_fov> 
        <image>
          <width>1280</width>
          <height>720</height>
        </image>
        <clip>
          <near>0.3</near>
          <far>20.0</far>
        </clip>
      </camera>
      <always_on>1</always_on>
      <update_rate>30</update_rate>
      <visualize>true</visualize>
      <topic>zed/image_raw</topic>
    </sensor>
  </gazebo>

  <gazebo>
    <plugin filename="ignition-gazebo-diff-drive-system" name="ignition::gazebo::systems::DiffDrive">
      <left_joint>front_left_wheel_joint</left_joint>
      <left_joint>rear_left_wheel_joint</left_joint>
      <right_joint>front_right_wheel_joint</right_joint>
      <right_joint>rear_right_wheel_joint</right_joint>
      <wheel_separation>2.095</wheel_separation>
      <wheel_radius>0.2</wheel_radius>
      <odom_publish_frequency>30</odom_publish_frequency>
      <topic>cmd_vel</topic>
      <odom_topic>odom</odom_topic>
      <frame_id>odom</frame_id>
      <child_frame_id>base_footprint</child_frame_id>
    </plugin>

    <plugin filename="ignition-gazebo-joint-state-publisher-system" name="ignition::gazebo::systems::JointStatePublisher">
      <topic>joint_states</topic>
      <joint_name>front_left_wheel_joint</joint_name>
      <joint_name>front_right_wheel_joint</joint_name>
      <joint_name>rear_left_wheel_joint</joint_name>
      <joint_name>rear_right_wheel_joint</joint_name>
    </plugin>
  </gazebo>

</robot>